Workbook
Name ChooseA: FEATS!$3:$3
Name CHOOSEANY: Math!$A$31:$M$31
Name CHOOSEONE: Math!$A$28:$D$28
Name DEF: Math!#REF!
Name Defence: Math!$FF$3:$FF$4
Name DefenceAC: STUFF!$A$1:$CU$2
Name DefenceFORT: STUFF!$A$3:$CU$4
Name DefenceREF: STUFF!#REF!
Name DefenceWILL: STUFF!$A$5:$CU$6
Name HP: Math!$FG$4:$FG$1175
Name LVL: Math!$FH$5:$FH$33
Name MonsterNames: #REF!
Name POWERS: STUFF!$A$7:$CU$38

Sheet START
A1: =B5/2 -> #REF! | B1: =C5/2 -> 0
A2: Initiative | D2: =SUM(5+B4) -> 10 | E2: You may choose any combo of the fallowing | O2: You may choose any combo of the fallowing
A3: Name | B3: Bat | E3: =HLOOKUP(E2,FEATS!1:2,2,FALSE) -> None | O3: =HLOOKUP(O2,FEATS!1:2,2,FALSE) -> None
A4: Level | B4: 5 | C4: EXP | D4: =TRANSPOSE(FEATS!C14) -> #REF!
A5: HP | B5: =VLOOKUP(B3,#REF!,2, FALSE) -> #REF! | C5: =HLOOKUP(A10,Math!A32:D38,2,FALSE) -> 0 | D5: =SUM(B5:C5) -> #REF!
A6: Weak | B6: =ROUNDUP(A1,0) -> #REF! | C6: =ROUNDUP(B1,0) -> 0 | D6: =SUM(B6:C6) -> #REF!
A7: AC | B7: =HLOOKUP(B3,STUFF!1:2,2, TRUE) -> 20 | C7: =HLOOKUP(A10,Math!A32:D38,3,FALSE) -> 0 | D7: =SUM(B7:C7) -> 20
A8: Fort | B8: =HLOOKUP(B3,STUFF!3:4,2, TRUE) -> 5 | C8: =HLOOKUP(A10,Math!A32:D38,4,FALSE) -> 0 | D8: =SUM(B8:C8) -> 5
A9: Will | B9: =HLOOKUP(B3,STUFF!5:6,2, TRUE) -> 14 | C9: =HLOOKUP(A10,Math!A32:D38,6,FALSE) -> 0 | D9: =SUM(B9:C9) -> 14
A10: You may choose one of the fallowing
E12: You may choose any combo of the fallowing | O12: You may choose any combo of the fallowing
E13: =HLOOKUP(E12,FEATS!1:2,2,FALSE) -> None | O13: =HLOOKUP(O12,FEATS!1:2,2,FALSE) -> None
E22: You may choose any combo of the fallowing | O22: You may choose any combo of the fallowing
E23: =HLOOKUP(E22,FEATS!1:2,2,FALSE) -> None | O23: =HLOOKUP(O22,FEATS!1:2,2,FALSE) -> None
A30: Monster dice equal to half the monsters level to a minimum of 1.
E32: You may choose any combo of the fallowing | O32: You may choose any combo of the fallowing | AL32: `
E33: =HLOOKUP(E32,FEATS!1:2,2,FALSE) -> None | O33: =HLOOKUP(O32,FEATS!1:2,2,FALSE) -> None
A103: 1 | B103: 0
A104: 2 | B104: 0
A105: 3 | B105: 0
A106: 4 | B106: 0
A107: 5 | B107: 0
A108: 6 | B108: 0
A109: 7 | B109: 0
A110: 8 | B110: 0
A111: 9 | B111: 0
A112: 10 | B112: Level 10 power
A113: 11
A114: 12
A115: 13
A116: 14
A117: 15
A118: 16
A119: 17
A120: 18
A121: 19
A122: 20
A123: 21
A124: 22
... A132: 30

Sheet Print
A1: HP | C1: =START!D5 -> #REF! | F1: =HLOOKUP(START!B3,STUFF!7:16,8,FALSE) -> The bat may fly up to 8 squares and makes one melee basic attack at any point during that movement. The bat doesn’t provoke opportunity attacks when moving away from the target of the attack.
A2: AC | C2: =START!D7 -> 20
A3: Fort | C3: =START!D8 -> 5
A4: Will | C4: =START!D9 -> 14 | F4: =HLOOKUP(START!B3,STUFF!7:16,10,FALSE) -> Fly 6 | U4: Monster dice equal to half the monsters level to a minimum of 1. | AG4: Initiative
A5: weak | C5: =START!D6 -> #REF! | AG5: =START!D2 -> 10
A6: =HLOOKUP(START!B3,STUFF!7:16,2,FALSE) -> Basic Melee attack: Bite 2+LVL vs AC damage 5 damage. disease: Rabies, a creature hit by this attack it will be filled with uncontrolled excitment and violance. The creature effected by this disease will attack the closest thing, friend or foe, and have a fear of water (save ends all). If the target fails it first save it will then fall unconsciouse (save ends). +1 dice everv 5 levels (i.e. levels 5,10,15..) | G6: =HLOOKUP(START!B3,STUFF!7:16,3,FALSE) -> 0 | N6: =HLOOKUP(START!B3,STUFF!7:16,4,FALSE) -> 0 | U6: =HLOOKUP(START!B3,STUFF!7:16,5,FALSE) -> 0 | AB6: =HLOOKUP(START!B3,STUFF!7:16,6,FALSE) -> 0 | AI6: =HLOOKUP(START!B3,STUFF!7:16,7,FALSE) -> 0
A30: =HLOOKUP(START!B3,STUFF!7:16,8,FALSE) -> The bat may fly up to 8 squares and makes one melee basic attack at any point during that movement. The bat doesn’t provoke opportunity attacks when moving away from the target of the attack. | F30: =HLOOKUP(START!B3,STUFF!7:16,9,FALSE) -> Blind Fighting You ignore the penalties for being blinded. | M30: =START!E3 -> None | U30: =START!O3 -> None | AB30: =START!E13 -> None | AI30: =START!O13 -> None
M44: =START!E23 -> None | U44: =START!O23 -> None | AB44: =START!E33 -> None | AI44: =START!O33 -> None

Sheet Math
FF4: 22 | FG4: 1 | FH4: 1
FH5: 2
FG6: 31 | FH6: 3
FH7: 4
FG8: 32 | FH8: 5
FH9: 6
FG10: 33 | FH10: 7
FG11: 34 | FH11: 8
FG12: 37 | FH12: 9
FG13: 38 | FH13: 10
FG14: 39 | FH14: 11
FG15: 40 | FH15: 12
FG16: 41 | FH16: 13
FG17: 42 | FH17: 14
FG18: 43 | FH18: 15
FG19: 44 | FH19: 16
FG20: 45 | FH20: 17
FG21: 46 | FH21: 18
... FG27: 52 | FH27: 24
A28: You may choose one of the fallowing | B28: Giant +100XP | C28: Huge +500XP | D28: Monstrous +1500xp | FG28: 53 | FH28: 25
A29: 0 | B29: 100 | C29: 500 | D29: 1500 | FG29: 54 | FH29: 26
A30: You may choose one of the fallowing | B30: Giant +100XP | C30: Huge +500XP | D30: Monstrous +1500xp | FG30: 55 | FH30: 27
A31: None | B31: +1 dice satge. i.e. 1d4 becomes 1d6, or 2d8 becomes 2d10. HP + 10x LVL (already applied) + 1 VS Saving rolls + 1 Initiative | C31: +2 dice satge. i.e. 1d4 becomes 1d8, or 2d8 becomes 2d12. + HP 20x LVL (already applied) + 5 VS Saving rolls + 3 Initiative + 1 base size + 1 Attack bonus X LVL | D31: +2 dice satge. i.e. 1d4 becomes 1d8, or 2d8 becomes 2d12. .+ 1 extra Damage dice i.e. 1d4 becomes 2d4. + HP 30x LVL (already applied) + 5 VS Saving rolls + 5 Initiative + 2 base size + 1 Attack bonus X LVL | FG31: 56 | FH31: 28
A32: You may choose one of the fallowing | B32: Giant +100XP | C32: Huge +500XP | D32: Monstrous +1500xp | E32: 25 | F32: 25 | G32: 25 | H32: 25 | I32: 100 | J32: 100 | K32: 200 | L32: 250 | M32: 300 | FG32: 57 | FH32: 29
A33: 0 | B33: =SUM(10*START!B4) -> 50 | C33: =SUM(20*START!B4) -> 100 | D33: =SUM(30*START!B4) -> 150 | FG33: 58 | FH33: 30
A34: 0 | B34: 0 | C34: 0 | D34: 1 | FG34: 59
A35: 0 | B35: 0 | C35: 0 | D35: 1 | FG35: 60
A36: 0 | B36: 0 | C36: 0 | D36: 1 | FG36: 61
A37: 0 | B37: 0 | C37: 0 | D37: 1 | FG37: 62
A38: 0 | B38: 0 | C38: =1+START!B4 -> 6 | D38: =1+START!B4 -> 6 | FG38: 63
FG39: 64
FG40: 65
FG41: 66
FG42: 67
FG43: 68
FG44: 69
FG45: 70
FG46: 71
FG47: 72
FG48: 73
...

Sheet STUFF
B1: Adult Dragon | C1: Ancient Dragon | D1: Bat | E1: Bat Swarm | F1: Blue Jell-O | G1: Bulbarsuara | H1: Chain Dark Shadow | I1: Charizard | J1: Charmander | K1: Charmeleon | L1: Clown | M1: Clown Swarm | N1: Two headed clown | O1: Happy (lord of chaos) | P1: Sad clown (champion of chaos) | Q1: Scary clown | R1: Creeps | S1: Dark Shadow | T1: Death Jump Spider | U1: Decrepit Skeleton | V1: Devourer | W1: Dier Rat | X1: Dier Wolf | Y1: Dilophosaurus | Z1: Disembodied hand | AA1: Doppelganger | AB1: Exploding Zombie | AC1: Fast Zombie | AD1: Flaming Skeleton | AE1: Giant (Arrow) | AF1: Giant (Rock) | AG1: Goblin | AH1: Goblin Archer | AI1: Goblin Minion | AJ1: Goblin Spider Rider | AK1: Goblin Theif | AL1: Goblin Trap Master | AM1: Great Worm | AN1: Green Jell-O | AO1: Hellfire Spout | AP1: Hells Scorpion | AQ1: Juvenile Dragon | AR1: Man Eatting Toilet | AS1: Masks | AT1: Mature Adult Dragon | AU1: No-u-see-ems | AV1: Octopus | AW1: Oger | AX1: Old Dragon | AY1: Ork Archer | AZ1: Ork Beserker | BA1: Ork Minion | BB1: Ork War Boss | BC1: Ork Warrior | BD1: Ornthiomimus Swarm | BE1: Overlord | BF1: Perodactyl | BG1: Poison Darts | BH1: Rat | BI1: Rat King | BJ1: Rat Swarm | BK1: Red Jell-O | BL1: Scorpion | BM1: Scorpion minions | BN1: Sith adept | BO1: Sith disciple | BP1: Sith knight | BQ1: Sith lord | BR1: Sith master | BS1: Sith Minion | BT1: Sith warrior | BU1: Shadow | BV1: Skeleton | BW1: Skull Lord | BX1: Slug | BY1: Snake Swarm | BZ1: Spider Swarm | CA1: Spined Shadow | CB1: Squirtle | CC1: Treee (Evil) | CD1: Toy Dolls | CE1: Trap Door | CF1: T-Rex | CG1: Vacuum | CH1: Velociraptor | CI1: Very Old Dragon | CJ1: Very Young Dargon | CK1: Viper | CL1: Wartorle | CM1: Wolf | CN1: Worg | CO1: Worm | CP1: Wormling | CQ1: Yellow Jell-O | CR1: Young Adult Dragon | CS1: Young Dragon | CT1: Zombie | CU1: Zombie Minion
A2: ac | B2: =21+START!B4 -> 26 | C2: =21+START!B4 -> 26 | D2: =15+START!B4 -> 20 | E2: =17+START!B4 -> 22 | F2: =22+START!B4 -> 27 | G2: =15+START!B4 -> 20 | H2: =17+START!B4 -> 22 | I2: =22+START!B4 -> 27 | J2: =22+START!B4 -> 27 | K2: =22+START!B4 -> 27 | L2: =17+START!B4 -> 22 | M2: =15+START!B4 -> 20 | N2: =17+START!B4 -> 22 | O2: =17+START!B4 -> 22 | P2: =17+START!B4 -> 22 | Q2: =17+START!B4 -> 22 | R2: =17+START!B4 -> 22 | S2: =17+START!B4 -> 22 | T2: =17+START!B4 -> 22 | U2: =15+START!B4 -> 20 | V2: =17+START!B4 -> 22 | W2: =16+START!B4 -> 21 | X2: =16+START!B4 -> 21 | Y2: =16+START!B4 -> 21 | Z2: =14+START!B4 -> 19 | AA2: =14+START!B4 -> 19 | AB2: =14+START!B4 -> 19 | AC2: =14+START!B4 -> 19 | AD2: =14+START!B4 -> 19 | AE2: =14+START!B4 -> 19 | AF2: =14+START!B4 -> 19 | AG2: =14+START!B4 -> 19 | AH2: =14+START!B4 -> 19 | AI2: =14+START!B4 -> 19 | AJ2: =14+START!B4 -> 19 | AK2: =14+START!B4 -> 19 | AL2: =14+START!B4 -> 19 | AM2: =21+START!B4 -> 26 | AN2: =21+START!B4 -> 26 | AO2: =21+START!B4 -> 26 | AP2: =21+START!B4 -> 26 | AQ2: =16+START!B4 -> 21 | AR2: =16+START!B4 -> 21 | AS2: =14+START!B4 -> 19 | AT2: =21+START!B4 -> 26 | AU2: =16+START!B4 -> 21 | AV2: =16+START!B4 -> 21 | AW2: =16+START!B4 -> 21 | AX2: =21+START!B4 -> 26 | AY2: =21+START!B4 -> 26 | AZ2: =16+START!B4 -> 21 | BA2: =21+START!B4 -> 26 | BB2: =21+START!B4 -> 26 | BC2: =21+START!B4 -> 26 | BD2: =16+START!B4 -> 21 | BE2: =16+START!B4 -> 21 | BF2: =16+START!B4 -> 21 | BH2: =14+START!B4 -> 19 | BI2: =14+START!B4 -> 19 | BJ2: =14+START!B4 -> 19 | BK2: =21+START!B4 -> 26 | BL2: =16+START!B4 -> 21 | BM2: =16+START!B4 -> 21 | BN2: =16+START!B4 -> 21 | BO2: =16+START!B4 -> 21 | BP2: =21+START!B4 -> 26 | BQ2: =21+START!B4 -> 26 | BR2: =21+START!B4 -> 26 | BS2: =17+START!B4 -> 22 | BT2: =16+START!B4 -> 21 | BU2: =17+START!B4 -> 22 | BV2: =21+START!B4 -> 26 | BW2: =21+START!B4 -> 26 | BX2: =16+START!B4 -> 21 | BY2: =14+START!B4 -> 19 | BZ2: =14+START!B4 -> 19 | CA2: =16+START!B4 -> 21 | CB2: =16+START!B4 -> 21 | CC2: =16+START!B4 -> 21 | CD2: =14+START!B4 -> 19 | CF2: =16+START!B4 -> 21 | CG2: =21+START!B4 -> 26 | CH2: =16+START!B4 -> 21 | CI2: =21+START!B4 -> 26 | CJ2: =13+START!B4 -> 18 | CK2: =14+START!B4 -> 19 | CL2: =21+START!B4 -> 26 | CM2: =14+START!B4 -> 19 | CN2: =16+START!B4 -> 21 | CO2: =21+START!B4 -> 26 | CP2: =13+START!B4 -> 18 | CQ2: =21+START!B4 -> 26 | CT2: =21+START!B4 -> 26 | CU2: =21+START!B4 -> 26
B3: Adult Dragon | C3: Ancient Dragon | D3: Bat | E3: Bat Swarm | F3: Blue Jell-O | G3: Bulbarsuara | H3: Chain Dark Shadow | I3: Charizard | J3: Charmander | K3: Charmeleon | L3: Clown | M3: Clown Swarm | N3: Two headed clown | O3: Happy (lord of chaos) | P3: Sad clown (champion of chaos) | Q3: Scary clown | R3: Creeps | S3: Dark Shadow | T3: Death Jump Spider | U3: Decrepit Skeleton | V3: Devourer | W3: Dier Rat | X3: Dier Wolf | Y3: Dilophosaurus | Z3: Disembodied hand | AA3: Doppelganger | AB3: Exploding Zombie | AC3: Fast Zombie | AD3: Flaming Skeleton | AE3: Giant (Arrow) | AF3: Giant (Rock) | AG3: Goblin | AH3: Goblin Archer | AI3: Goblin Minion | AJ3: Goblin Spider Rider | AK3: Goblin Theif | AL3: Goblin Trap Master | AM3: Great Worm | AN3: Green Jell-O | AO3: Hellfire Spout | AP3: Hells Scorpion | AQ3: Juvenile Dragon | AR3: Man Eatting Toilet | AS3: Masks | AT3: Mature Adult Dragon | AU3: No-u-see-ems | AV3: Octopus | AW3: Oger | AX3: Old Dragon | AY3: Ork Archer | AZ3: Ork Beserker | BA3: Ork Minion | BB3: Ork War Boss | BC3: Ork Warrior | BD3: Ornthiomimus Swarm | BE3: Overlord | BF3: Perodactyl | BG3: Poison Darts | BH3: Rat | BI3: Rat King | BJ3: Rat Swarm | BK3: Red Jell-O | BL3: Scorpion | BM3: Scorpion minions | BN3: Sith adept | BO3: Sith disciple | BP3: Sith knight | BQ3: Sith lord | BR3: Sith master | BS3: Sith Minion | BT3: Sith warrior | BU3: Shadow | BV3: Skeleton | BW3: Skull Lord | BX3: Slug | BY3: Snake Swarm | BZ3: Spider Swarm | CA3: Spined Shadow | CB3: Squirtle | CC3: Treee (Evil) | CD3: Toy Dolls | CE3: Trap Door | CF3: T-Rex | CG3: Vacuum | CH3: Velociraptor | CI3: Very Old Dragon | CJ3: Very Young Dargon | CK3: Viper | CL3: Wartorle | CM3: Wolf | CN3: Worg | CO3: Worm | CP3: Wormling | CQ3: Yellow Jell-O | CR3: Young Adult Dragon | CS3: Young Dragon | CT3: Zombie | CU3: Zombie Minion
A4: fort | B4: =5+START!B4 -> 10 | C4: =5+START!B4 -> 10 | D4: =0+START!B4 -> 5 | E4: =0+START!B4 -> 5 | F4: =5+START!B4 -> 10 | G4: =5+START!B4 -> 10 | H4: =5+START!B4 -> 10 | I4: =5+START!B4 -> 10 | J4: =5+START!B4 -> 10 | K4: =5+START!B4 -> 10 | L4: =0+START!B4 -> 5 | M4: =2+START!B4 -> 7 | N4: =2+START!B4 -> 7 | O4: =5+START!B4 -> 10 | P4: =2+START!B4 -> 7 | Q4: =1+START!B4 -> 6 | R4: =1+START!B4 -> 6 | S4: =5+START!B4 -> 10 | T4: =5+START!B4 -> 10 | U4: =0+START!B4 -> 5 | V4: =5+START!B4 -> 10 | W4: =0+START!B4 -> 5 | X4: =3+START!B4 -> 8 | Y4: =5+START!B4 -> 10 | Z4: =0+START!B4 -> 5 | AA4: =0+START!B4 -> 5 | AB4: =0+START!B4 -> 5 | AC4: =0+START!B4 -> 5 | AD4: =0+START!B4 -> 5 | AE4: =5+START!B4 -> 10 | AF4: =7+START!B4 -> 12 | AG4: =0+START!B4 -> 5 | AH4: =0+START!B4 -> 5 | AI4: =5+START!B4 -> 10 | AJ4: =2+START!B4 -> 7 | AK4: =0+START!B4 -> 5 | AL4: =0+START!B4 -> 5 | AM4: =5+START!B4 -> 10 | AN4: =5+START!B4 -> 10 | AO4: =5+START!B4 -> 10 | AP4: =5+START!B4 -> 10 | AQ4: =5+START!B4 -> 10 | AR4: =5+START!B4 -> 10 | AS4: =1+START!B4 -> 6 | AT4: =5+START!B4 -> 10 | AU4: =5+START!B4 -> 10 | AV4: =5+START!B4 -> 10 | AW4: =7+START!B4 -> 12 | AX4: =5+START!B4 -> 10 | AY4: =5+START!B4 -> 10 | AZ4: =5+START!B4 -> 10 | BA4: =7+START!B4 -> 12 | BB4: =5+START!B4 -> 10 | BC4: =5+START!B4 -> 10 | BD4: =5+START!B4 -> 10 | BE4: =5+START!B4 -> 10 | BF4: =5+START!B4 -> 10 | BG4: =5+START!B4 -> 10 | BH4: =5+START!B4 -> 10 | BI4: =5+START!B4 -> 10 | BJ4: =5+START!B4 -> 10 | BK4: =5+START!B4 -> 10 | BL4: =5+START!B4 -> 10 | BM4: =5+START!B4 -> 10 | BN4: =0+START!B4 -> 5 | BO4: =0+START!B4 -> 5 | BP4: =1+START!B4 -> 6 | BQ4: =1+START!B4 -> 6 | BR4: =1+START!B4 -> 6 | BS4: =1+START!B4 -> 6 | BT4: =1+START!B4 -> 6 | BU4: =0+START!B4 -> 5 | BV4: =0+START!B4 -> 5 | BW4: =2+START!B4 -> 7 | BX4: =2+START!B4 -> 7 | BY4: =5+START!B4 -> 10 | BZ4: =5+START!B4 -> 10 | CA4: =2+START!B4 -> 7 | CB4: =5+START!B4 -> 10 | CC4: =5+START!B4 -> 10 | CD4: =1+START!B4 -> 6 | CE4: =7+START!B4 -> 12 | CF4: =5+START!B4 -> 10 | CG4: =0+START!B4 -> 5 | CH4: =5+START!B4 -> 10 | CI4: =5+START!B4 -> 10 | CJ4: =5+START!B4 -> 10 | CK4: =1+START!B4 -> 6 | CL4: =5+START!B4 -> 10 | CM4: =2+START!B4 -> 7 | CN4: =5+START!B4 -> 10 | CO4: =5+START!B4 -> 10 | CP4: =5+START!B4 -> 10 | CQ4: =5+START!B4 -> 10 | CR4: =5+START!B4 -> 10 | CS4: =5+START!B4 -> 10 | CT4: =0+START!B4 -> 5 | CU4: =0+START!B4 -> 5
B5: Adult Dragon | C5: Ancient Dragon | D5: Bat | E5: Bat Swarm | F5: Blue Jell-O | G5: Bulbarsuara | H5: Chain Dark Shadow | I5: Charizard | J5: Charmander | K5: Charmeleon | L5: Clown | M5: Clown Swarm | N5: Two headed clown | O5: Happy (lord of chaos) | P5: Sad clown (champion of chaos) | Q5: Scary clown | R5: Creeps | S5: Dark Shadow | T5: Death Jump Spider | U5: Decrepit Skeleton | V5: Devourer | W5: Dier Rat | X5: Dier Wolf | Y5: Dilophosaurus | Z5: Disembodied hand | AA5: Doppelganger | AB5: Exploding Zombie | AC5: Fast Zombie | AD5: Flaming Skeleton | AE5: Giant (Arrow) | AF5: Giant (Rock) | AG5: Goblin | AH5: Goblin Archer | AI5: Goblin Minion | AJ5: Goblin Spider Rider | AK5: Goblin Theif | AL5: Goblin Trap Master | AM5: Great Worm | AN5: Green Jell-O | AO5: Hellfire Spout | AP5: Hells Scorpion | AQ5: Juvenile Dragon | AR5: Man Eatting Toilet | AS5: Masks | AT5: Mature Adult Dragon | AU5: No-u-see-ems | AV5: Octopus | AW5: Oger | AX5: Old Dragon | AY5: Ork Archer | AZ5: Ork Beserker | BA5: Ork Minion | BB5: Ork War Boss | BC5: Ork Warrior | BD5: Ornthiomimus Swarm | BE5: Overlord | BF5: Perodactyl | BG5: Poison Darts | BH5: Rat | BI5: Rat King | BJ5: Rat Swarm | BK5: Red Jell-O | BL5: Scorpion | BM5: Scorpion minions | BN5: Sith adept | BO5: Sith disciple | BP5: Sith knight | BQ5: Sith lord | BR5: Sith master | BS5: Sith Minion | BT5: Sith warrior | BU5: Shadow | BV5: Skeleton | BW5: Skull Lord | BX5: Slug | BY5: Snake Swarm | BZ5: Spider Swarm | CA5: Spined Shadow | CB5: Squirtle | CC5: Treee (Evil) | CD5: Toy Dolls | CE5: Trap Door | CF5: T-Rex | CG5: Vacuum | CH5: Velociraptor | CI5: Very Old Dragon | CJ5: Very Young Dargon | CK5: Viper | CL5: Wartorle | CM5: Wolf | CN5: Worg | CO5: Worm | CP5: Wormling | CQ5: Yellow Jell-O | CR5: Young Adult Dragon | CS5: Young Dragon | CT5: Zombie | CU5: Zombie Minion
A6: will | B6: =13+START!B4 -> 18 | C6: =15+START!B4 -> 20 | D6: =9+START!B4 -> 14 | E6: =10+START!B4 -> 15 | F6: =15+START!B4 -> 20 | G6: =15+START!B4 -> 20 | H6: =15+START!B4 -> 20 | I6: =15+START!B4 -> 20 | J6: =15+START!B4 -> 20 | K6: =15+START!B4 -> 20 | L6: =9+START!B4 -> 14 | M6: =9+START!B4 -> 14 | N6: =9+START!B4 -> 14 | O6: =15+START!B4 -> 20 | P6: =15+START!B4 -> 20 | Q6: =15+START!B4 -> 20 | R6: =15+START!B4 -> 20 | S6: =17+START!B4 -> 22 | T6: =15+START!B4 -> 20 | U6: =9+START!B4 -> 14 | V6: =15+START!B4 -> 20 | W6: =9+START!B4 -> 14 | X6: =15+START!B4 -> 20 | Y6: =10+START!B4 -> 15 | Z6: =15+START!B4 -> 20 | AA6: =15+START!B4 -> 20 | AB6: =8+START!B4 -> 13 | AC6: =9+START!B4 -> 14 | AD6: =9+START!B4 -> 14 | AE6: =8+START!B4 -> 13 | AF6: =8+START!B4 -> 13 | AG6: =9+START!B4 -> 14 | AH6: =9+START!B4 -> 14 | AI6: =9+START!B4 -> 14 | AJ6: =9+START!B4 -> 14 | AK6: =9+START!B4 -> 14 | AL6: =9+START!B4 -> 14 | AM6: =15+START!B4 -> 20 | AN6: =15+START!B4 -> 20 | AP6: =15+START!B4 -> 20 | AQ6: =15+START!B4 -> 20 | AR6: =15+START!B4 -> 20 | AS6: =15+START!B4 -> 20 | AT6: =15+START!B4 -> 20 | AU6: =15+START!B4 -> 20 | AV6: =15+START!B4 -> 20 | AW6: =10+START!B4 -> 15 | AX6: =15+START!B4 -> 20 | AY6: =9+START!B4 -> 14 | AZ6: =9+START!B4 -> 14 | BA6: =9+START!B4 -> 14 | BB6: =9+START!B4 -> 14 | BC6: =9+START!B4 -> 14 | BD6: =10+START!B4 -> 15 | BE6: =15+START!B4 -> 20 | BF6: =9+START!B4 -> 14 | BG6: 0 | BH6: =9+START!B4 -> 14 | BI6: =15+START!B4 -> 20 | BJ6: =15+START!B4 -> 20 | BK6: =15+START!B4 -> 20 | BL6: =11+START!B4 -> 16 | BM6: =15+START!B4 -> 20 | BN6: =15+START!B4 -> 20 | BO6: =15+START!B4 -> 20 | BP6: =15+START!B4 -> 20 | BQ6: =17+START!B4 -> 22 | BR6: =17+START!B4 -> 22 | BS6: =15+START!B4 -> 20 | BT6: =15+START!B4 -> 20 | BU6: =17+START!B4 -> 22 | BV6: =10+START!B4 -> 15 | BW6: =15+START!B4 -> 20 | BX6: =15+START!B4 -> 20 | BY6: =15+START!B4 -> 20 | BZ6: =17+START!B4 -> 22 | CA6: =17+START!B4 -> 22 | CB6: =15+START!B4 -> 20 | CC6: =15+START!B4 -> 20 | CD6: =15+START!B4 -> 20 | CF6: =10+START!B4 -> 15 | CG6: =11+START!B4 -> 16 | CH6: =11+START!B4 -> 16 | CI6: =15+START!B4 -> 20 | CJ6: =15+START!B4 -> 20 | CK6: =11+START!B4 -> 16 | CL6: =15+START!B4 -> 20 | CM6: =15+START!B4 -> 20 | CN6: =15+START!B4 -> 20 | CO6: =15+START!B4 -> 20 | CP6: =15+START!B4 -> 20 | CQ6: =15+START!B4 -> 20 | CR6: =15+START!B4 -> 20 | CS6: =15+START!B4 -> 20 | CT6: =11+START!B4 -> 16 | CU6: =11+START!B4 -> 16
A7: Choose one | B7: Adult Dragon | C7: Ancient Dragon | D7: Bat | E7: Bat Swarm | F7: Blue Jell-O | G7: Bulbarsuara | H7: Chain Dark Shadow | I7: Charizard | J7: Charmander | K7: Charmeleon | L7: Clown | M7: Clown Swarm | N7: Two headed clown | O7: Happy (lord of chaos) | P7: Sad clown (champion of chaos) | Q7: Scary clown | R7: Creeps | S7: Dark Shadow | T7: Death Jump Spider | U7: Decrepit Skeleton | V7: Devourer | W7: Dier Rat | X7: Dier Wolf | Y7: Dilophosaurus | Z7: Disembodied hand | AA7: Doppelganger | AB7: Exploding Zombie | AC7: Fast Zombie | AD7: Flaming Skeleton | AE7: Giant (Arrow) | AF7: Giant (Rock) | AG7: Goblin | AH7: Goblin Archer | AI7: Goblin Minion | AJ7: Goblin Spider Rider | AK7: Goblin Theif | AL7: Goblin Trap Master | AM7: Great Worm | AN7: Green Jell-O | AO7: Hellfire Spout | AP7: Hells Scorpion | AQ7: Juvenile Dragon | AR7: Man Eatting Toilet | AS7: Masks | AT7: Mature Adult Dragon | AU7: No-u-see-ems | AV7: Octopus | AW7: Oger | AX7: Old Dragon | AY7: Ork Archer | AZ7: Ork Beserker | BA7: Ork Minion | BB7: Ork War Boss | BC7: Ork Warrior | BD7: Ornthiomimus Swarm | BE7: Overlord | BF7: Perodactyl | BG7: Poison Darts | BH7: Rat | BI7: Rat King | BJ7: Rat Swarm | BK7: Red Jell-O | BL7: Scorpion | BM7: Scorpion minions | BN7: Sith adept | BO7: Sith disciple | BP7: Sith knight | BQ7: Sith lord | BR7: Sith master | BS7: Sith Minion | BT7: Sith warrior | BU7: Shadow | BV7: Skeleton | BW7: Skull Lord | BX7: Slug | BY7: Snake Swarm | BZ7: Spider Swarm | CA7: Spined Shadow | CB7: Squirtle | CC7: Treee (Evil) | CD7: Toy Dolls | CE7: Trap Door | CF7: T-Rex | CG7: Vacuum | CH7: Velociraptor | CI7: Very Old Dragon | CJ7: Very Young Dargon | CK7: Viper | CL7: Wartorle | CM7: Wolf | CN7: Worg | CO7: Worm | CP7: Wormling | CQ7: Yellow Jell-O | CR7: Young Adult Dragon | CS7: Young Dragon | CT7: Zombie | CU7: Zombie Minion
A8: 2 | B8: Basic Melee: Bite Reach 3 6+LVL vs. AC 2d6+LVL damage. +1 dice everv 5 levels (i.e. levels 5,10,15..) Or 7 damage +LVL Pirecing damage = to monster LVL. | C8: Basic Melee: Bite Reach 3 10+LVL vs. AC 2d6+LVL damage. Pirecing damage = to monster LVL. | D8: Basic Melee attack: Bite 2+LVL vs AC damage 5 damage. disease: Rabies, a creature hit by this attack it will be filled with uncontrolled excitment and violance. The creature effected by this disease will attack the closest thing, friend or foe, and have a fear of water (save ends all). If the target fails it first save it will then fall unconsciouse (save ends). +1 dice everv 5 levels (i.e. levels 5,10,15..) | E8: Basic Melee attack: Bite 2+LVL vs AC damage 1d6 + LVL damage. disease: Rabies, a creature hit by this attack it will be filled with uncontrolled excitment and violance. The creature effected by this disease will attack the closest thing, friend or foe, and have a fear of water (save ends all). If the target fails it first save it will then fall unconsciouse (save ends). +1 dice everv 5 levels (i.e. levels 5,10,15..) | F8: Basic Ranged: Jell-o Shot Range: 10 4+LVL vs AC Damage: 2d6+ LVL damage. +1 dice everv 5 levels (i.e. levels 5,10,15..) | G8: Basic Melee: Tackle 4 + LVL vs AC 1d6 + LVL Damage. +1 dice everv 5 levels (i.e. levels 5,10,15..) | H8: Basic Melee: Shadow chain whip Reach 2 Attack: 4+ LVL vs. AC Damage 2d6 + LVL dark damage, +1 dice everv 5 levels (i.e. levels 5,10,15..) | I8: Basic Melee: Bite Reach 2 5+ LVL vs. AC Damage 1d8 + LVL, Pirecing damage = to monster LVL. +1 dice everv 5 levels (i.e. levels 5,10,15..) | J8: Basic Melee: Scratch Reach 1 2+ LVL vs. AC Damage 1d4 + LVL. +1 dice everv 5 levels (i.e. levels 5,10,15..) | K8: Basic Melee: Bite Pirecing damage = to monster LVL. Reach 2 3+ LVL vs. AC Damage 4+LVL | L8: Basic Melee attack; Bite 3+LVL vs. AC 5 damage . | M8: Melee attack: Swarm of Teeth 2 + LVL vs. AC 1d6 + LVL damage, and ongoing damage equal to the monsters level and fear (save ends both). Pirecing damage = to monster LVL. +1 dice everv 5 levels (i.e. levels 5,10,15..) | N8: Melee attack Giant spiked Club Reach 2 4 + LVL vs. AC 2d6 + LVL damage and the target is dazed and takes a -5+ Monster level to recharge thier powers. (save ends) +1 dice everv 5 levels (i.e. levels 5,10,15..) | O8: Ranged attack: trick flower Range:6. Attack: 1d4 + LVL vs AC. Hit: 1d6 + LVL water damage and the target is blinded (save ends) +1 dice everv 5 levels (i.e. levels 5,10,15..) | Q8: Basic Melee attack; Squeeky hammer 3+LVL vs. AC 1d8 + LVL damage. +1 dice everv 5 levels (i.e. levels 5,10,15..) | R8: Basic Melee: Shadow Claws 2+LVL vs. AC 5 Damage, -1 xLVL to targets AC (save ends) | S8: Basic Melee: Shadow Claws Reach 2, +12 vs. AC 2d6 damage -5 to targets AC ( save ends) Pirecing damage = to monster LVL. +1 dice everv 5 levels (i.e. levels 5,10,15..) | U8: Basic Melee: Longsword Weapon 2+ LVL vs. AC 5 damage. | V8: Ranged: Shadow Breath close cone 5 2 + LVL vs. will The target is dazed (save ends) if the target does not save he then falls unconscious for 1+LVL rounds. | W8: Basic Melee attack; Bite 2+LVL vs. AC 1d6 + LVL damage, the target is diseased. +1 dice everv 5 levels (i.e. levels 5,10,15..) Disease: Feeble (save ends) every turn that the character fails his saving throw the DC for the save increases by 1 to a max of 15 | X8: Basic Melee: Bite 3 + lvl vs. AC; 1d6 + lvl damage, or 2d6 + lvl damage against a prone target. +1 dice everv 5 levels (i.e. levels 5,10,15..) Pirecing damage = to monster LVL. | Y8: Basic Range: Spit poison 3+ LVL vs. AC 5 damage and the target is blinded and poisoned =monster lvl +4 (save ends both) +1 dice everv 5 levels (i.e. levels 5,10,15..) | Z8: Basic Ranged:Finger Gun Range 15 3+ LVL vs. AC 1d4 + LVL damage. +1 dice everv 5 levels (i.e. levels 5,10,15..) | AA8: Melee: Shadow Claws Reach 2, 2 + LVL vs. AC 1d6 + LVL dark damage -3 to targets AC ( save ends) +1 dice everv 5 levels (i.e. levels 5,10,15..) | AB8: Basic Melee: Longsword Weapon + 2 + LVL vs. AC; 1d6 + LVL damage, and the target is marked until the end of the skeleton’s next turn; see also speed of the dead. +1 dice everv 5 levels (i.e. levels 5,10,15..) | AC8: Melee attack: punch Attack: +2 + LVL vs AC 1d4 +LVL damage +1 dice everv 5 levels (i.e. levels 5,10,15..) | AD8: Melee: Firey strike +2+LVL vs. AC 1d6 + LVL fire damage +1 dice everv 5 levels (i.e. levels 5,10,15..) | AE8: Ranged attack: Giant Arrow Range:20 +4+LVL vs AC Hit:2D8+1D6+LVL Damage +1 dice everv 5 levels (i.e. levels 5,10,15..) Special: takes a turn to reload | AF8: Melee attack Giant Club Reach 3 4 + LVL vs. AC 2d8 + LVL damage and the target is dazed (save ends) +1 dice everv 5 levels (i.e. levels 5,10,15..) | AG8: Melee: Spear Reach 2 +2 + LVL vs AC 5 Damage | AH8: 5 Damage | AI8: Ranged: Gun Range 10 +5+LVL vs AC Damage 2d6+LVL +1 dice everv 5 levels (i.e. levels 5,10,15..) Pirecing damage = to monster LVL. | AJ8: Melee: Spear (Goblin) Reach 2 +2 + LVL vs AC Damage 1d4+LVL. This monster may make an attack for both the spider and goblin in the same turn. +1 dice everv 5 levels (i.e. levels 5,10,15..) Pirecing damage = to monster LVL. | AK8: Ranged: Gun Range 10 +2+LVL vs AC Damage 1d6+LVL. +1 dice everv 5 levels (i.e. levels 5,10,15..) | AL8: Ranged: Gun Range 10 +2+LVL vs AC Damage 1d6+LVL. +1 dice everv 5 levels (i.e. levels 5,10,15..) | AM8: Melee: Bite Pirecing damage = to monster LVL. Reach 3 12 + LVL vs. AC 2d6+LVL damage. +1 dice everv 5 levels (i.e. levels 5,10,15..) | AN8: Melee: Poison hit +4+LVL vs. AC Damage: 1d6 and a ongoing 1+LVL poison damage (save ends). | AO8: Trigger: When a character enters the blast area of one of the hellfire spouts, the trap makes its first attack as an immediate reaction. It then enters the initiative order directly after the creature that triggered it, attacking each round. | AP8: Basic Melee: Claws Fire +2 + LVL vs. AC 2d6 + LVL damage, and the target is grabbed (until escape). A grabbed target takes 1+ half LVL fire damage at the start of the hells scorpion’s turn. +1 dice everv 5 levels (i.e. levels 5,10,15..) | AQ8: Melee: Bite Reach 3 4 + LVL vs. AC 2d6+LVL damage. Pirecing damage = to monster LVL. +1 dice everv 5 levels (i.e. levels 5,10,15..) | AR8: Basic Melee: Bite +2 + LVL vs. AC 1d6+ LVL damage and the target is grabbed. +1 dice everv 5 levels (i.e. levels 5,10,15..) Pirecing damage = to monster LVL. | AS8: Melee Dominate +2+ LVL vs. will Damage 1d4 and the target is dominated (save ends) +1 dice everv 5 levels (i.e. levels 5,10,15..) | AT8: Melee: Bite Reach 3 2 + LVL vs. AC 2d6+LVL damage. Pirecing damage = to monster LVL. | AU8: Melee: Under Armor Bite +3 + LVL vs. AC Damage: 1d6 + LVL if no-u-see-ems attack the same target next turn the target is at -1 AC +LVL (save ends). +1 dice everv 5 levels (i.e. levels 5,10,15..) Pirecing damage = to monster LVL. | AV8: Melee : Tentacle Hold recharge 4+ Reach: 3 +4 + LVL vs. AC 1d4 damage and the target is grabbed, you may move the target so that it is adjacent. +1 dice everv 5 levels (i.e. levels 5,10,15..) Special: you may use Tentacle Hold 4 times on differant targets in the same turn. | AW8: Melee attack Giant Club Reach 2 4 + LVL vs. AC 2d6 + LVL damage and the target is dazed (save ends). +1 dice everv 5 levels (i.e. levels 5,10,15..) | AX8: Melee: Bite Reach 3 8 + LVL vs. AC 2d6+LVL damage. +1 dice everv 5 levels (i.e. levels 5,10,15..) Pirecing damage = to monster LVL. | AY8: Ranged: Big Gun Range 10 +1 + LVL vs AC 5 Damage | AZ8: Melee attack Greataxe +3 + LVL vs. AC; Critical 17+ 1d6 +LVL damage +1 dice everv 5 levels (i.e. levels 5,10,15..) | BA8: Melee attack Crack em on the ead +8+LVL vs. AC; 2d8 + LVL damage. +1 dice everv 5 levels (i.e. levels 5,10,15..) | BB8: Basic Melee attack Hammer + 3 + LVL vs. AC 2d6 + LVL damage. +1 dice everv 5 levels (i.e. levels 5,10,15..) | BC8: Melee Battleaxe +3+ LVL vs. AC; 1d6+LVL damage. +1 dice everv 5 levels (i.e. levels 5,10,15..) | BD8: Basic Melee Swarm bite 2+ vs AC 5 damage | BE8: Melee: Longsword Weapon + 3+ LVL vs. AC; 1d6 + LVL damage +1 dice everv 5 levels (i.e. levels 5,10,15..) | BF8: Basic Melee attack Bite 3 + LVL vs AC 2d6 + LVL damage. +1 dice everv 5 levels (i.e. levels 5,10,15..) | BG8: Trigger: When a character enters the line of one of the Poison darts, the trap makes its first attack as an immediate reaction. It then enters the initiative order directly after the creature that triggered it, attacking each round. | BH8: Basic Melee attack: Bite 2+LVL vs. AC hit:Disease: Feeble (save ends) every turn that the character fails his saving throw the DC for the save increases by 1 to a max of 15 | BI8: Basic Melee: Scratch Reach 1 2+ LVL vs. AC Damage 2d4 + LVL and the target is Diseased. +1 dice everv 5 levels (i.e. levels 5,10,15..) Disease: Feeble (save ends) every turn that the character fails his saving throw the DC for the save increases by 1 to a max of 15 | BJ8: Melee attack: Swarm of Teeth 2 + LVL vs. AC 1d6 + LVL damage, and ongoing damage equal to the monsters level (save ends), Diseased. Disease: Feeble (save ends) every turn that the character fails his saving throw the DC for the save increases by 1 to a max of 15 | BK8: Basic Melee Attack: Slam 4+ LVL Vs AC Damage: 1d6 + LVL. +1 dice everv 5 levels (i.e. levels 5,10,15..) | BL8: Melee: Claws +3 + LVL vs. AC; 1d6 + LVL damage, and a Medium or smaller target is grabbed (until escape). A grabbed target takes 5 damage at the start of the scorpion’s turn. +1 dice everv 5 levels (i.e. levels 5,10,15..) | BM8: Melee Sting Poison +3 + LVL vs. ACitude; 1d6 + LVL damage, and the target takes ongoing poison damage equal to half MLVL and is immobilized (save ends both). +1 dice everv 5 levels (i.e. levels 5,10,15..) | BN8: Light saber. Melee. +2+lvl vs AC. 1d6+lvl damage ignores damage resistance +1 dice everv 5 levels (i.e. levels 5,10,15..) Pirecing damage = to monster LVL. | BO8: Light saber. Melee. +2+lvl vs AC. 1d6+lvl damage ignores damage resistance +1 dice everv 5 levels (i.e. levels 5,10,15..) Pirecing damage = to monster LVL. | BP8: Light saber. Melee. +4+lvl vs AC. 1d6+lvl damage ignores damage resistance. +1 dice everv 5 levels (i.e. levels 5,10,15..) Pirecing damage = to monster LVL. | BQ8: Light saber. Melee. +5+lvl vs AC. 1d6+lvl damage ignores damage resistance. +1 dice everv 5 levels (i.e. levels 5,10,15..) Pirecing damage = to monster LVL. | BR8: Light saber. Melee. +5+lvl vs AC. 1d6+lvl damage ignores damage resistance Pirecing damage = to monster LVL. +1 dice everv 5 levels (i.e. levels 5,10,15..) | BS8: Light saber. Melee. +5+lvl vs AC. 2d6+lvl damage ignores damage resistance. +1 dice everv 5 levels (i.e. levels 5,10,15..) Pirecing damage = to monster LVL. | BT8: Light saber. Melee. +5+lvl vs AC. 1d6+lvl damage ignores damage resistance. +1 dice everv 5 levels (i.e. levels 5,10,15..) Pirecing damage = to monster LVL. | BU8: Melee: Shadow Claws Reach 2, 2+ LVL vs. AC 2d6 + LVL damage -2 to targets AC ( save ends). +1 dice everv 5 levels (i.e. levels 5,10,15..) | BV8: Basic Melee: Longsword Weapon +2+LVL vs. AC; 1d6 + Level damage | BW8: Basic Melee: Bone Staff (head 1) +4 + LVL vs. AC; 1d6 + LVL damage plus 1d4 dark damage. +1 dice everv 5 levels (i.e. levels 5,10,15..) | BX8: Melee:Tongue Reach 2 +3 + LVL vs. AC 2d4 + LVL acid Damage. +1 dice everv 5 levels (i.e. levels 5,10,15..) | BY8: Melee: Coil +2 + LVL vs. AC Damage: 5 and the target is grabbed. | BZ8: Melee: Swarm of Fangs +2 + LVL vs. AC; 1d6 + LVL damage, and ongoing Half LVL poison damage (save ends). +1 dice everv 5 levels (i.e. levels 5,10,15..) | CA8: Melee: Shadow Claws Reach 2, 2+ LVL vs. AC 1d4 + LVL dark damage -3 to targets AC ( save ends). +1 dice everv 5 levels (i.e. levels 5,10,15..) | CB8: Melee: Bite +2 + LVL vs. AC Damage 1d6+ LVL +1 dice everv 5 levels (i.e. levels 5,10,15..) | CC8: Melee: Whip Reach 2 +2+LVL vs. AC Damage: 1d6+LVL. +1 dice everv 5 levels (i.e. levels 5,10,15..) | CD8: Basic Ranged: Stare Range 13 +3+LVL vs. will 2d4 + LVL damage and the target is stunned (save ends). +1 dice everv 5 levels (i.e. levels 5,10,15..) | CE8: Trigger: When a character moves threw the square with the trap door, the trap is triggered as an immediate reaction. | CF8: Basic Melee: Bite Reach 3 4 + LVL vs. AC 2d6 + twice LVL and the target is grabbed (save ends). Pirecing damage = to monster LVL. | CG8: Free action Close: Suck Close Blast 5 3 + LVL vs AC Effect all in the blast are pulled up to 3 squares. | CH8: Melee: Bite 3 + LVL vs AC 1D6 + LVL damage. +1 dice everv 5 levels (i.e. levels 5,10,15..) Pirecing damage = to monster LVL. | CI8: Melee: Bite Reach 3 9 + LVL vs. AC 2d6+LVL damage. +1 dice everv 5 levels (i.e. levels 5,10,15..) Pirecing damage = to monster LVL. | CJ8: Melee: Bite Reach 3 2 + LVL vs. AC 2d6+LVL damage. +1 dice everv 5 levels (i.e. levels 5,10,15..) Pirecing damage = to monster LVL. | CK8: Basic Melee: Bite +2 + LVL vs. AC; 1d6 + LVL damage, and viper may make a secondary attack against the same target. +1 dice everv 5 levels (i.e. levels 5,10,15..) Secondary Attack: +3 + LVL vs. ACitude; 1d4 + LVL poison damage, and ongoing Half LVL poison damage (save ends). +1 dice everv 5 levels (i.e. levels 5,10,15..) Pirecing damage = to monster LVL. | CL8: Melee: Bite Reach 2 +2+LVL vs. AC Damage 1d6 + LVL+1 dice everv 5 levels (i.e. levels 5,10,15..) Pirecing damage = to monster LVL. | CM8: Melee:Bite 2+LVL vs. AC 1d6 + LVL damage, or 2d6 + LVL damage against a down target. +1 dice everv 5 levels (i.e. levels 5,10,15..) Pirecing damage = to monster LVL. | CN8: Basic Melee: Bite 3+ LVL vs. AC 2d6 + LVL damage, and ongoing damage equal to the Worges level (save ends). +1 dice everv 5 levels (i.e. levels 5,10,15..) Pirecing damage = to monster LVL. | CO8: Melee: Bite Reach 3 11 + LVL vs. AC 2d6+LVL damage. +1 dice everv 5 levels (i.e. levels 5,10,15..) Pirecing damage = to monster LVL. | CP8: Melee: Bite Reach 3 1 + LVL vs. AC 2d6+LVL damage. +1 dice everv 5 levels (i.e. levels 5,10,15..) Pirecing damage = to monster LVL. | CQ8: Mimic yellow may use any attack used against it in the last turn with a attack power of + 2 + LVL, in addition yellow may use any weapons stuck in it. if no attacks were made against it last turn Yellow may not attack this turn. | CR8: Melee: Bite Reach 3 5 + LVL vs. AC 2d6+LVL damage. +1 dice everv 5 levels (i.e. levels 5,10,15..) Pirecing damage = to monster LVL. | CS8: Melee: Bite Reach 3 3 + LVL vs. AC 2d6+LVL damage. +1 dice everv 5 levels (i.e. levels 5,10,15..) Pirecing damage = to monster LVL. | CT8: Melee attack: slam ( charge attack) Attack: +2+LVL vs AC 1d6 + LVL damage +1 dice everv 5 levels (i.e. levels 5,10,15..) | CU8: Basic Melee attack: slam (charge attack) Attack: +5 + LVL vs AC 2d6 + LVL damage +1 dice everv 5 levels (i.e. levels 5,10,15..)
A9: 3 | B9: Melee: Claw Reach 3 6+LVL vs. AC 2d6+LVL damage. +1 dice everv 5 levels (i.e. levels 5,10,15..) Pirecing damage = to monster LVL. | C9: Melee: Claw Reach 3 10+LVL vs. AC 2d6+LVL damage. +1 dice everv 5 levels (i.e. levels 5,10,15..) Pirecing damage = to monster LVL. | E9: The bat may fly up to 8 squares and makes one melee basic attack at any point during that movement. The bat doesn’t provoke opportunity attacks when moving away from the target of the attack. | F9: Close: Jell-O Blast recharge 4+ Close blast 3 4 + LVL vs AC Damage: monster LVL + 4. | G9: Basic Melee: Vine Whip Reach: 2 4 + LVL vs AC 2d6 + LVL damage +1 dice everv 5 levels (i.e. levels 5,10,15..) | H9: Melee Shadow Chain wrap Reach 2 Attack: 4+LVL vs. AC Hit: the target is restrained. You may only restrain one Pc at a time | I9: Melee: Scratch Reach 2 5+ LVL vs. AC Hit: 2d6 + LVL. Pirecing damage = to monster LVL. +1 dice everv 5 levels (i.e. levels 5,10,15..) | J9: Close Growl Close blast 1 4+LVL vs. Will Effect: all Enemys in the blast are at -1 +monster LVL attack. | K9: Melee: Scratch Reach 1 3+ LVL vs. AC Damage 4+LVL | L9: Basic Melee: Hammer Reach 1 4+ LVL vs. AC Hit: 1d6 + LVL and takes a -5+ Monster level to recharge thier powers (save ends). +1 dice everv 5 levels (i.e. levels 5,10,15..) | M9: Swarm Attack aura 1: the clown swarm makes a basic attack as a free action against each enemy that begins its turn in the aura. | N9: Ranged attack: trick flower Range:6. Attack: 3 + LVL vs AC. Hit: 5 water damage and the target is blinded (save ends) +1 dice everv 5 levels (i.e. levels 5,10,15..) | O9: close attack: swirling chaos Close Blast 3 Targets: all in the blast Attack: 1d4 + LVL vs AC. 1d6 + LVL damage and the targets are pushed back 2 squares knocked down and dazed (save ends dazed) Effect: Happy may teleport 1d4 squares in a random direction. +1 dice everv 5 levels (i.e. levels 5,10,15..) | Q9: Ranged attack: Bang Pistol Range:6. Attack: 2 + LVL vs AC. 1d6 + LVL damage. +1 dice everv 5 levels (i.e. levels 5,10,15..) | R9: Melee: Dominating Reach recharge 5+ Reach 2, 2+LVL vs. Will 1d4+LVL Damage and the target is dominated (save ends). +1 dice everv 5 levels (i.e. levels 5,10,15..) | S9: Melee: Dominating Reach Recharge 4+ Recharge 4+ Reach 2, +12 vs. Will 2d6 Damage and the target is dominated (save ends) +1 dice everv 5 levels (i.e. levels 5,10,15..) | U9: Basic Ranged: Shortbow Range 15 2 + LVL vs. AC; 2d4 +LVL damage +1 dice everv 5 levels (i.e. levels 5,10,15..) | V9: Melee: Devour Shadow Affects only unconscious targets 2 + LVL vs. AC 1D6 + LVL dark damage and the Devourer heals 15hp this attack does not awaken unconscious targets. +1 dice everv 5 levels (i.e. levels 5,10,15..) | W9: Basic Melee: Scratch Reach 1 2+ LVL vs. AC Damage 1d4 + LVL Disease: Feeble (save ends) every turn that the character fails his saving throw the DC for the save increases by 1 to a max of 15. +1 dice everv 5 levels (i.e. levels 5,10,15..) | X9: Pack Hunter: If a wolf flanks the target, the target is also knocked down on a hit. | Y9: Melee: Bite 3+ LVL vs AC 1d6 + LVL damage and the target takes an ongoing poison damage equal to the monsters level (Save ends). Pirecing damage = to monster LVL. +1 dice everv 5 levels (i.e. levels 5,10,15..) | Z9: Melee: Strangle Recharge 4+ 3+ LVL vs. AC 2d6 + LVL damage and the target is grabbed (save ends) If the target fails its first save it then falls stunned (save ends both). +1 dice everv 5 levels (i.e. levels 5,10,15..) | AA9: Range: Perfect Copy. Range:10 When a doppelganger uses this power, it can assume the appearance of specific individual. | AB9: Speed of the Dead When making an opportunity attack, the skeleton gains a +2 bonus to the attack roll and deals an extra 1d6 damage. | AC9: Melee attack: bite Recharge 5+ Attack: +10 vs AC Damage: 5 Nanobots Infection. Nanobot infection; target takes an ongoing 2 damage (save ends). If the target fails the first save the target becomes slowed, if the target fails a third time or the target becomes weakened, then it is dominated becoming the same type of zombie that just attacked it (Save ends both). | AD9: Ranged: Flames +2+LVL vs AC 1d6 + LVL fire damage +1 dice everv 5 levels (i.e. levels 5,10,15..) | AE9: Melee attack Giant Club Reach 3 1 + LVL vs. AC 2d6 + LVL damage and the target is dazed (save ends) +1 dice everv 5 levels (i.e. levels 5,10,15..) | AF9: Ranged Attack: Throw Rock Range: 8, Blast 1 Attack: 1+LVL vs. AC Hit: 2D6+LVL damage +1 dice everv 5 levels (i.e. levels 5,10,15..) | AG9: Favored Enemy: Cats Gain a + 2 attack power and damage vs favored enemy, and a further +1 attack power at level 5. | AH9: Favored Enemy: Cats Gain a + 2 attack power and damage vs favored enemy, and a further +1 attack power at level 5. | AI9: Melee: Spear Reach 2 +5 + LVL vs AC Damage 2d4+LVL. | AJ9: Ranged: Gun(Goblin) Range 10 +2+LVL vs AC Damage 1d6+LVL This monster may make an attack for both the spider and goblin in the same turn. +1 dice everv 5 levels (i.e. levels 5,10,15..) | AK9: Melee: Dagger +2 + LVL vs AC 5 Damage | AL9: Melee: Spear Reach 2 +2 + LVL vs AC Damage 1d4+LVL. +1 dice everv 5 levels (i.e. levels 5,10,15..) Pirecing damage = to monster LVL. | AM9: Melee: Claw Reach 3 12 + LVL vs. AC 2d6+LVL damage. +1 dice everv 5 levels (i.e. levels 5,10,15..) | AN9: Special: Sticky Trigger when ever Green is hit with a melee attack. Effect: weapon is stuck to Jell-o and the target takes 1+LVL poison damage, (save ends poison) | AO9: Attack: Close Cone 3 Targets: Creatures in blast Attack: +10 vs. AC Hit: 3d4 + LVL fire damage and ongoing 1+Half LVL fire damage (save ends). +1 dice everv 5 levels (i.e. levels 5,10,15..) Miss: Half damage, and no ongoing damage. | AP9: Melee: Hellish Sting Fire, Poison + 4 + LVL vs. ACitude; 1d6 + LVL damage, and the target takes ongoing 2 + Half LVL fire and poison damage and is weakened (save ends both). The hells scorpion can use this attack against a target it has grabbed. +1 dice everv 5 levels (i.e. levels 5,10,15..) | AQ9: Melee: Claw Reach 3 4 + LVL vs. AC 2d6+LVL damage. +1 dice everv 5 levels (i.e. levels 5,10,15..) | AR9: Melee: Flush: the target must be grabbed +3 + LVL vs. AC 2d6 damage and an on going water damage equal to the monsters level (Save ends). +1 dice everv 5 levels (i.e. levels 5,10,15..) | AS9: Ranged: Fear Range Close cone 3 +4+ LVL vs Will Damage 2d6 damage and the target is feared. +1 dice everv 5 levels (i.e. levels 5,10,15..) | AT9: Melee: Claw Reach 3 2 + LVL vs. AC 2d6+LVL damage. +1 dice everv 5 levels (i.e. levels 5,10,15..) | AU9: Melee: Poison Sting +3 + LVL vs. AC Damage: 1D6 +LVL and an ongoing 2+half LVL poison damage (save ends). +1 dice everv 5 levels (i.e. levels 5,10,15..) | AV9: Basic Melee: Bite the target must be grabbed +3 + LVL vs. AC 2d6 +LVL damage . +1 dice everv 5 levels (i.e. levels 5,10,15..) Pirecing damage = to monster LVL. | AW9: Melee attack: Javelin Range 8 3+LVL vs. AC 1d6+ LVL damage. +1 dice everv 5 levels (i.e. levels 5,10,15..) | AX9: Melee: Claw Reach 3 8 + LVL vs. AC 2d6+LVL damage. +1 dice everv 5 levels (i.e. levels 5,10,15..) | AY9: Melee attack dagger +2 + LVL vs. AC; 1d4+ LVL damage. +1 dice everv 5 levels (i.e. levels 5,10,15..) | AZ9: Melee attack Whirlwind Close blast 1 +3 + LVL vs. AC Critical 17+ 1d4 +LVL damage +1 dice everv 5 levels (i.e. levels 5,10,15..) | BB9: Chaos Hammer Close Blast 1 +3 + LVL vs. AC 1d6 + LVL force damage, and the target is knocked down. +1 dice everv 5 levels (i.e. levels 5,10,15..) Miss: Half damage, and the target is not knocked down | BC9: Melee attack Whirlwind Close blast 1 +3 + LVL vs. AC Critical 17+ 1d4 +LVL damage +1 dice everv 5 levels (i.e. levels 5,10,15..) | BD9: Melee: Swarm over 3+ lvl vs AC 1d4 + twice lvl damage +1 dice everv 5 levels (i.e. levels 5,10,15..) | BE9: Close: Blast Back + 3+ LVL vs. AC; 1d4 damage and the targets are push back 2 squares. +1 dice everv 5 levels (i.e. levels 5,10,15..) | BF9: Basic: Melee Grab 4+ LVL vs. AC, 1d6 + LVL damage and the target is grabed. Carry: you may move the grabed target along with you and drop it at any point during your move, if you are using this attack as part of the striffing attack. | BG9: Attack: Close Line 4 Target: closest creature to the trap within the line Attack: +4 + LVL vs. AC Hit: 2d4 + LVL poison damage, and an ongoing 3+ half LVL poison damage (save ends). +1 dice everv 5 levels (i.e. levels 5,10,15..) | BI9: Melee attack Bite 4+ LVL vs. AC 2d6 + LVL damage and the target is diseased. Disease: Feeble (save ends) every turn that the character fails his saving throw the DC for the save increases by 1 to a max of 15 Pirecing damage = to monster LVL. | BK9: Special: Rage Trigger: When Red is weakened Effect: + half LVL damage and attack power bonus. | BL9: Melee: Sting Poison +3 + LVL vs. ACitude; 1d4 + LVL damage, and the target takes ongoing 5 poison damage and is immobilized (save ends both). The scorpion can use this attack against a target it has grabbed. +1 dice everv 5 levels (i.e. levels 5,10,15..) | BM9: Basic Melee: Claws +3 + LVL vs. AC; 1d6 + LVL damage, and a Medium or smaller target is grabbed (until escape). A grabbed target takes 1 + LVL damage at the start of the scorpion’s turn. +1 dice everv 5 levels (i.e. levels 5,10,15..) | BO9: Force pull/push. Range 10 Target: One monster Attack: 2+LVL vs. AC Hit: 1d4 + lvl damage, and you push or pull the target 1 square. +1 dice everv 5 levels (i.e. levels 5,10,15..) Special: This power can be used as a ranged basic attack | BP9: Force pull/push. Range 10 Target: One monster Attack: 4+LVL vs. AC Hit: 1d4 + lvl damage, and you push or pull the target 1 square. +1 dice everv 5 levels (i.e. levels 5,10,15..) Special: This power can be used as a ranged basic attack | BQ9: Force pull/push. Range 10 Target: One monster Attack: 5+LVL vs. AC Hit: 1d4 + lvl damage, and you push or pull the target 1 square. +1 dice everv 5 levels (i.e. levels 5,10,15..) Special: This power can be used as a ranged basic attack | BR9: Force pull/push. Range 10 Target: One monster Attack: 5+LVL vs. AC Hit: 2d4 + lvl damage, and you push or pull the target 1 square. +1 dice everv 5 levels (i.e. levels 5,10,15..) Special: This power can be used as a ranged basic attack | BS9: Force pull/push. Range 10 Target: One monster Attack: 5+LVL vs. AC Hit: 2d4 + lvl damage, and you push or pull the target 1 square. +1 dice everv 5 levels (i.e. levels 5,10,15..) Special: This power can be used as a ranged basic attack | BT9: Force pull/push. Range 10 Target: One monster Attack: 2+LVL vs. AC Hit: 1d4 + lvl damage, and you push or pull the target 1 square. +1 dice everv 5 levels (i.e. levels 5,10,15..) Special: This power can be used as a ranged basic attack | BU9: Melee: Dominating Reach Recharge 6+ Reach 2, 2 + LVL vs. Will 5+ LVL Damage and the target is dominated (save ends) +1 dice everv 5 levels (i.e. levels 5,10,15..) | BV9: Basic Ranged: Shortbow Ranged 15 +3+LVL vs. AC; 5 damage | BW9: Ranged: Skull of Bonechilling Fear (Head 2) Ranged 10 +4 + LVL vs. Will 1d6 + LVL cold damage, and the target is pushed 5 squares. +1 dice everv 5 levels (i.e. levels 5,10,15..) | BX9: Ranged: Spit Acid Range: 8 + 2 + LVL vs AC 1d6 + LVL acid damage. +1 dice everv 5 levels (i.e. levels 5,10,15..) | BY9: Melee: Bite, +2 + LVL vs. AC Damage: 1D6 + LVL poison damage and an ongoing Half LVL poison damage (save ends). | CA9: Melee attack: Hide in the shadows 2+ LVL vs. AC 1d6 + LVL dark damage and the spined shadow hides in the targets shadow becoming invisible. +1 dice everv 5 levels (i.e. levels 5,10,15..) | CB9: Shell Target: Self Squirtle gains + half LVL bonus to all deference until the end of the encounter. | CC9: Melee: Limb Slam Target: 0ne enemy Attack: +2+LVL vs AC Damage: 2d6+LVL. +1 dice everv 5 levels (i.e. levels 5,10,15..) | CD9: Melee: Behind you +3 + LVL vs. AC Special: the doll attacks then teleports 4 squares away. 1d4 + 2xLVL damage | CE9: Attack: Target: all creatures within the trap Attack: +4 + LVL vs. AC Hit: 2d6 + LVL falling damage, and an ongoing 1+ half LVL bleeding damage (save ends) | CF9: Melee: Claw Reach 3 2 + Level vs. AC 1d4 + lvl damage. +1 dice everv 5 levels (i.e. levels 5,10,15..) | CG9: Close: Explode bag Close Blast 2 +5+LVL vs. AC Damage: 2d6 +LVL and the target is knocked down. Vacuum is destroyed. +1 dice everv 5 levels (i.e. levels 5,10,15..) | CH9: Melee: Claw 4+ LVL vs. AC critical: 18+ damge: x3 2d6 + LVL damage. +1 dice everv 5 levels (i.e. levels 5,10,15..) | CI9: Melee: Claw Reach 3 9 + LVL vs. AC 2d6+LVL damage. +1 dice everv 5 levels (i.e. levels 5,10,15..) Pirecing damage = to monster LVL. | CJ9: Melee: Claw Reach 3 2 + LVL vs. AC 2d6+LVL damage. +1 dice everv 5 levels (i.e. levels 5,10,15..) Pirecing damage = to monster LVL. | CL9: Utility – Withdraw Self Wartortle gains + Half LVL bonus to all deference until the end of the encounter. | CN9: Melee: Claw 3 + LVL vs. AC 2d6+LVL damage. +1 dice everv 5 levels (i.e. levels 5,10,15..) Pirecing damage = to monster LVL. | CO9: Melee: Claw Reach 3 11 + LVL vs. AC 2d6+LVL damage. +1 dice everv 5 levels (i.e. levels 5,10,15..) Pirecing damage = to monster LVL. | CP9: Melee: Claw Reach 3 1 + LVL vs. AC 2d6+LVL damage. +1 dice everv 5 levels (i.e. levels 5,10,15..) Pirecing damage = to monster LVL. | CQ9: Special: Sticky Trigger when ever jell-o is hit with a melee attack. Effect: weapon is stuck to Jell-o | CR9: Melee: Claw Reach 3 5 + LVL vs. AC 2d6+LVL damage. +1 dice everv 5 levels (i.e. levels 5,10,15..) Pirecing damage = to monster LVL. | CS9: Melee: Claw Reach 3 3 + LVL vs. AC 2d6+LVL damage. +1 dice everv 5 levels (i.e. levels 5,10,15..) Pirecing damage = to monster LVL. | CT9: Melee attack: punch Reach 2 Attack: +2LVL vs AC 1d6 + LVL damage +1 dice everv 5 levels (i.e. levels 5,10,15..) | CU9: Melee attack: punch Attack: +7 + lvl vs AC 2d4 + LVL damage +1 dice everv 5 levels (i.e. levels 5,10,15..)
